Workbook

Sheet 02.2026
A1: LIQUIDACION DE GASTOS
A2: MES DE LIQUIDACIÓN (CIERRE): FEBRERO 2026 MES DE VENCIMIENTO DE LA LIQUIDACION: MARZO 2026
A3: ADMINISTRACIÓN CONSORCIO D&F Administracion SARMIENTO 356,358,360 CUIT: 27-25108998-7 CUIT: 30-71412062-6 Matricula: RPAC N° 1772 / RPA N° 17517 SARMIENTO 356 -360 - Lomas de Zamora (Bs. As.) Telefonos: 4742-6085 / 1167867049 / 1168939477 CLAVE SUTERH: Bynnon 1686 - Adrogue (1846) Mail: dyfadmconsorcios@gmail.com
A4: Estado de cuentas y prorrateo PERIODO FEBRERO 2025 VENCIMIENTO 15/03/2026 | S4: Tasa de interés: 7,90%
A5: UF | B5: DEPTO | C5: PROPIETARIOS | D5: PORCENTUAL | E5: SALDO ANTERIOR | G5: PAGOS | I5: SALDO
A6: 1 | B6: 1°A - 356 | C6: SEVERINO | D6: 0.0156 | E6: 393470 | G6: 392000 | I6: 1470
A7: 2 | B7: 1°C - 356 | C7: FERNANDEZ | D7: 0.0107 | E7: 287636 | G7: 287636 | I7: $ -
A8: 3 | B8: 1°B - 356 | C8: ALVAREZ MARIA INES | D8: 0.0103 | E8: 279259 | G8: 279259 | I8: $ -
A9: 4 | B9: 1°A - 360 | C9: PERRI | D9: 0.0103 | E9: 279259 | G9: 279259 | I9: $ -
A10: 5 | B10: 1°C - 360 | C10: BONFANTI SANDRA | D10: 0.0114 | E10: 302295 | G10: 300000 | I10: 2295
A11: 6 | B11: 1°B - 360 | C11: MAGLIOLO SILVIA | D11: 0.0172 | E11: 423761 | G11: 423761 | I11: $ -
A12: 7 | B12: 2°A - 356 | C12: MALDAJAN | D12: 0.016 | E12: 1103703 | G12: 1104000 | I12: -297
A13: 8 | B13: 2°C - 356 | C13: CARROSO | D13: 0.0109 | E13: 291824 | G13: 291824 | I13: $ -
A14: 9 | B14: 2°B - 356 | C14: BLAUSTEIN | D14: 0.0103 | E14: 279259 | G14: 279259 | I14: $ -
A15: 10 | B15: 2°A - 360 | C15: LOPARDO | D15: 0.0102 | E15: 277164 | G15: 277164 | I15: $ -
A16: 11 | B16: 2°C - 360 | C16: MENA | D16: 0.0107 | E16: 287636 | G16: 287636 | I16: $ -
A17: 12 | B17: 2°B - 360 | C17: PUMA ROSA | D17: 0.0155 | E17: 388159 | G17: 388159 | I17: $ -
A18: 13 | B18: 3°A - 356 | C18: GRIMM | D18: 0.0159 | E18: 396536 | G18: 396536 | I18: $ -
A19: 14 | B19: 3°C - 356 | C19: GRIMM | D19: 0.0107 | E19: 287636 | G19: 287636 | I19: $ -
A20: 15 | B20: 3°B - 356 | C20: FERNANDEZ | D20: 0.0102 | E20: 277164 | G20: 277164 | I20: $ -
A21: 16 | B21: 3°A - 360 | C21: IANELLO | D21: 0.0103 | E21: 279259 | G21: 279259 | I21: $ -
A22: 17 | B22: 3°C - 360 | C22: MUSACCHIO | D22: 0.0125 | E22: 325332 | G22: $ - | I22: 325332
A23: 18 | B23: 3°B - 360 | C23: ROMBOUTS DIETER | D23: 0.0155 | E23: 388159 | G23: 388159 | I23: $ -
A24: 19 | B24: 4°A - 356 | C24: RIONEGRO CARLOS ALBERTO | D24: 0.0171 | E24: 421666 | G24: 421666 | I24: $ -
A25: 20 | B25: 4°C - 356 | C25: GIANOLA | D25: 0.0107 | E25: 287636 | G25: 287636 | I25: $ -
A26: 21 | B26: 4°B - 356 | C26: FRANCO | D26: 0.0119 | E26: 610758 | G26: 610758 | I26: $ -
A27: 22 | B27: 4°A - 360 | C27: DOMINGUEZ OSVALDO | D27: 0.0119 | E27: 312766 | G27: 312766 | I27: $ -
A28: 23 | B28: 4°C - 360 | C28: CALANDRA | D28: 0.0124 | E28: 323237 | G28: 323237 | I28: $ -
A29: 24 | B29: 4°B - 360 | C29: TAKEDA LAURA NANCY | D29: 0.0156 | E29: 390253 | G29: 390253 | I29: $ -
A30: 25 | B30: 5°A - 356 | C30: SUAREZ PATRICIO | D30: 0.0156 | E30: 390188 | G30: 390188 | I30: $ -
A31: 26 | B31: 5°C - 356 | C31: LANATI | D31: 0.0108 | E31: 390812 | G31: $ - | I31: 390812
A32: 27 | B32: 5°B - 356 | C32: NIBALI AGUSTINA DENISE | D32: 0.0102 | E32: 277164 | G32: 277164 | I32: $ -
A33: 28 | B33: 5°A - 360 | C33: FLOLASCO SILVINA | D33: 0.0102 | E33: 277164 | G33: 277164 | I33: $ -
A34: 29 | B34: 5°C - 360 | C34: PUMAR RICARDO | D34: 0.0112 | E34: 298107 | G34: 298107 | I34: $ -
A35: 30 | B35: 5°B - 360 | C35: JAIMES MARISA | D35: 0.0175 | E35: 430043 | G35: $ - | I35: 430043
A36: 31 | B36: 6°A - 356 | C36: FIORENZA ROSARIO | D36: 0.0227 | E36: 538943 | G36: 538943 | I36: $ -
A37: 32 | B37: 6°C - 356 | C37: JUIZ K | D37: 0.0123 | E37: 321143 | G37: 321143 | I37: $ -
A38: 33 | B38: 6°B - 356 | C38: DELGADO | D38: 0.0118 | E38: 310672 | G38: 310672 | I38: $ -
A39: 34 | B39: 6°A - 360 | C39: IGLESIAS | D39: 0.0139 | E39: 697281 | G39: 697281 | I39: $ -
A40: 35 | B40: 6°C - 360 | C40: FAPSA | D40: 0.0123 | E40: 321143 | G40: 321143 | I40: $ -
...

Sheet CUOTA SINDICAL

Sheet COMISIONES

Sheet 25413

Sheet LA UNION E HIJOS

Sheet DIFERENCIAS ENCONTRADAS
A1: DIFERENCIAS ENTRE LO LOQUIDADO Y LO REALMENTE ABONADO
A2: FECHA | B2: DETALLE | C2: PAGO REALIZADO | D2: EN LIQUIDACIÓN | E2: DIF | F2: OBSERVACION
A3: 46361 | B3: SUELDO JUAN | C3: ='12.2025'!L113 -> #REF! | D3: 1089415 | E3: =C3-D3 -> #REF! | F3: IMPORTE DEVENGADO NO REAL (LIQUIDACION MES ANTERIOR $ 1,054,813.41)
A4: 46361 | B4: SUELDO JAVIER | C4: ='12.2025'!L132 -> #REF! | D4: 681302 | E4: =C4-D4 -> #REF! | F4: IMPORTE DEVENGADO NO REAL (LIQUIDACION MES ANTERIOR $ 662,491.25) SE DEPOSITARON 20000 DE MAS
A5: 46361 | B5: SUELDO RAMIREZ | C5: ='12.2025'!L148 -> #REF! | D5: 688435 | E5: =C5-D5 -> #REF! | F5: IMPORTE DEVENGADO NO REAL (LIQUIDACION MES ANTERIOR $ 745,574.00) SE DEPOSITARON 58023 DE MENOS
A6: 46374 | B6: AGUINALDO JUAN | C6: ='12.2025'!L114 -> #REF! | D6: 1287347 | E6: =C6-D6 -> #REF! | F6: IMPORTE LIQUIDADO EN EL MES ANTERIOR CON PROVISION TOTAL MENOR AL REAL - AUNQUE EL PAGO CORRESPONDE LA RECAUDACION FUE MENOR
A7: 46374 | B7: AGUINALDO JAVIER | C7: ='12.2025'!L133 -> #REF! | D7: 0 | E7: =C7-D7 -> #REF! | F7: IMPORTE LIQUIDADO EN EL MES ANTERIOR CON PROVISION TOTAL MENOR AL REAL - AUNQUE EL PAGO CORRESPONDE LA RECAUDACION FUE MENOR
A8: 46374 | B8: AGUINALDO RAMIREZ | C8: ='12.2025'!L149 -> #REF! | D8: 0 | E8: =C8-D8 -> #REF! | F8: IMPORTE LIQUIDADO EN EL MES ANTERIOR CON PROVISION TOTAL MENOR AL REAL - AUNQUE EL PAGO CORRESPONDE LA RECAUDACION FUE MENOR
A9: 46368 | B9: CARGAS SOCIALES | C9: ='12.2025'!L153 -> #REF! | D9: ='12.2025'!F153 -> #REF! | E9: =C9-D9 -> #REF! | F9: IMPORTE DEVENGADO NO REAL (LIQUIDACION MES ANTERIOR $ 1,546,772.50)
A10: 46368 | B10: FED ARG DE TRAB | C10: 15578.92 | D10: 679584.04 | E10: =C10-D10 -> -664005.12 | F10: IMPORTE DEVENGADO NO REAL (LIQUIDACION MES ANTERIOR CON COMPROBANTES EN EL MES ANTERIOR)
A11: 46368 | B11: SIND UN TRAB REN | C11: 140210.29 | D11: 0 | E11: =C11-D11 -> 140210.29 | F11: IMPORTE DEVENGADO NO REAL (LIQUIDACION MES ANTERIOR CON COMPROBANTES EN EL MES ANTERIOR)
A12: 46368 | B12: FED ARG TRAB REN | C12: 255053.93 | D12: 0 | E12: =C12-D12 -> 255053.93 | F12: IMPORTE DEVENGADO NO REAL (LIQUIDACION MES ANTERIOR CON COMPROBANTES EN EL MES ANTERIOR)
A13: LA UNION E HIJOS SRL | B13: COMPRA DE PINTURA CUOATA 01/02 | C13: 1360711.4 | D13: 3500000 | E13: =C13-D13 -> -2139288.6 | F13: SE LIQUIDO UN GASTO EXTRAORDINARIO MUY SUPERIOR A LO FINALMENTE FACTURADO Y ESTA RECAUDACIÓN NO FUE INCLUIDA EN EL RESUMEN DE FDR QUE IBAN DESTINADOS A PINTURA, MIENTRAS QUE LOS GASTOS SI ESTAN DETALLADOS.
A14: 46368 | B14: CLEANNIG SERVICE - MATERIALES DE LIMPIEZA | C14: 175845 | D14: 212900 | E14: =C14-D14 -> -37055 | F14: SEGUN ESTO SE ABONO POR MENOS, AUNQUE EL COMPROBANTE NO ES VÁLIDO COMO FACTURA. TENEMOS LA FACTURA?
A15: 46361 | B15: SEGURIDAD NOVIEMBRE 2025 FACTURA N° 00002-0044 | C15: 2372281.2 | D15: 3704325 | E15: =D15-C15 -> 1332043.8 | F15: IMPORTE DEVENGADO NO REAL (LIQUIDACION MES ANTERIOR CON COMPROBANTES EN EL MES ANTERIOR)
A17: LIQUIDADO SIN PAGO REGISTRADO EN CUENTA
A18: YPF CICLOS | B18: COMPRA DE COMBUSTIBLE FACT Nro 00011-53269 | C18: 32000.04 | D18: COMPROBANTE CON FECHA 14/10 21:25
A19: YPF CICLOS | B19: COMPRA DE COMBUTIBLR FACT.Nro 0001-53270 | C19: 32000.04 | D19: COMPROBANTE CON FECHA 14/10 21:27
A20: ASCENSORES GUILLEMI | B20: Mantenimiento ascensores DICIEMBRE | C20: 87866.77 | D20: FACTURA DE 120000 FECHA 5/1
A21: FOTOCOPIAS DE EXPENSAS NOVIEMBRE | C21: 18900 | D21: SIN COMPROBANTE
A23: PAGO REGISTRADOS QUE NO FIGURAN EN ESTRACTO Y SI CONSIDERA LA ADMINISTRACIÓN
B24: CALOGNE RICARDO | C24: 9°A - 356 | D24: 65000
A26: GASTOS NO LIQUIDADOS QUE FUERON DEBITADOS DE CUENTA
A27: 46361 | B27: RAFAEL MOREL ROMAN | C27: 700000 | D27: CON RECIBI FECHA 5/12 | E27: PUESTO EN ESE RESUMEN DE FDR MAL COMPUTADO
A28: 46368 | B28: LUIS DE LA PAS PAVON | C28: 160000 | D28: SIN NINGUN COMPROBANTE EN ESTE MES | E28: ENTIENDO QUE PAGARON LA DIFERENCIA LIQUIDADA EL MES PASADO EN ESTE MES SALDANDO EL ERROR MARCADO EL MES ANTERIOR
A29: 46368 | B29: RAFAEL MOREL ROMAN | C29: 1000000 | D29: CON RECIBI FECHA 12/12 | E29: PUESTO EN ESE RESUMEN DE FDR MAL COMPUTADO
A30: 46374 | B30: RAFAEL MOREL ROMAN | C30: 1700000 | D30: CON RECIBI FECHA 18/12 | E30: PUESTO EN ESE RESUMEN DE FDR MAL COMPUTADO
A31: 46378 | B31: RAFAEL MOREL ROMAN | C31: 1500000 | D31: CON RECIBI FECHA 29/12 | E31: PUESTO EN ESE RESUMEN DE FDR MAL COMPUTADO
