Workbook

Sheet 11.2025
C1: LIQUIDACION DE GASTOS
A2: MES DE LIQUIDACIÓN (CIERRE): | B2: NOVIEMBRE 2025 | C2: MES DE VENCIMIENTO DE LA LIQUIDACION: | D2: DICIEMBRE 2025
A3: ADMINISTRACIÓN | C3: CONSORCIO
A4: Estado de cuentas y prorrateo PERIODO NOVIEMBRE 2025 VENCIMIENTO 15/12/2025 Tasa de interés: 7,30%
A5: UF | B5: DEPTO | C5: PROPIETARIOS | D5: PORCENTUAL | E5: SALDO ANTERIOR | F5: PAGOS | G5: SALDO | H5: Fecha | I5: Monto Pagado
A6: 1 | B6: 1°A - 356 | C6: SEVERINO | D6: 0.0156 | E6: 217571 | F6: 217600 | G6: -29 | H6: 46343 | I6: 217600 | J6: DEP EFVO
A7: 2 | B7: 1°C - 356 | C7: FERNANDEZ | D7: 0.0107 | E7: 158684 | F7: 158684 | G7: $ - | H7: 46336 | I7: 158684.02 | J7: =I7=F7 -> FALSE
A8: 3 | B8: 1°B - 356 | C8: ALVAREZ MARIA INES | D8: 0.0103 | E8: 153876 | F8: 153876 | G8: $ - | H8: 46346 | I8: 153876 | J8: =I8=F8 -> TRUE
A9: 4 | B9: 1°A - 360 | C9: PERRI | D9: 0.0103 | E9: 153876 | F9: 153876 | G9: $ - | I9: 153876 | J9: =I9=F9 -> TRUE
A10: 5 | B10: 1°C - 360 | C10: BONFANTI | D10: 0.0114 | E10: 155168 | F10: 155168 | G10: $ - | H10: 46346 | I10: 155168 | J10: =I10=F10 -> TRUE | K10: JUAN MANUEL FAGUNDEZ | L10: 46330 | M10: 153876
A11: 6 | B11: 1°B - 360 | C11: MAGLIOLO SILVIA | D11: 0.0172 | E11: 236825 | F11: 236825 | G11: $ - | H11: 46339 | I11: 236825.06 | J11: =I11=F11 -> FALSE | K11: RODRIGUEZ OUTES | L11: 46330 | M11: 152674
A12: 7 | B12: 2°A - 356 | C12: MALDAJAN | D12: 0.016 | E12: 451468 | F12: 208800 | G12: 242668 | H12: 46353 | I12: 208800 | J12: =I12=F12 -> TRUE | K12: AGUSTINA CASTRO ACE | L12: 46330 | M12: 152674
A13: 8 | B13: 2°C - 356 | C13: CARROSO | D13: 0.0109 | E13: 161089 | F13: 161089 | G13: $ - | H13: 46337 | I13: 161089 | J13: =I13=F13 -> TRUE | K13: JUAN IGNACIO DIAZ | L13: 46331 | M13: 172139
A14: 9 | B14: 2°B - 356 | C14: BLAUSTEIN | D14: 0.0103 | E14: 153876 | F14: 153876 | G14: $ - | I14: 153876 | J14: =I14=F14 -> TRUE | K14: ROSA ANTONIA GUALLIN | L14: 46333 | M14: 153876
A15: 10 | B15: 2°A - 360 | C15: LOPARDO | D15: 0.0102 | E15: 152674 | F15: 152674 | G15: $ - | I15: 152674 | J15: =I15=F15 -> TRUE | K15: JUAN IGNACIO SAEZ GA | L15: 46333 | M15: 158684
A16: 11 | B16: 2°C - 360 | C16: MENA | D16: 0.0107 | E16: 158684 | F16: 158684 | G16: $ - | I16: 158684 | J16: =I16=F16 -> TRUE | K16: JONTE LUCAS MARTIN | L16: 46333 | M16: 158684
A17: 12 | B17: 2°B - 360 | C17: PUMA ROSA | D17: 0.0155 | E17: 216388 | F17: 216388 | G17: $ - | H17: 46343 | I17: 216388 | J17: =I17=F17 -> TRUE | K17: COL SOFIA TRINIDAD | L17: 46336 | M17: 177919
A18: 13 | B18: 3°A - 356 | C18: GRIMM | D18: 0.0159 | E18: 221197 | F18: 221197 | G18: $ - | H18: 46344 | I18: 379881 | J18: TRUE | K18: ORTIZ WENDY | L18: 46336 | M18: 152674
A19: 14 | B19: 3°C - 356 | C19: GRIMM | D19: 0.0107 | E19: 158684 | F19: 158684 | G19: $ - | H19: 46344 | J19: TRUE | K19: COMBER DENISE | L19: 11/!1 | M19: 152674
A20: 15 | B20: 3°B - 356 | C20: FERNANDEZ | D20: 0.0102 | E20: 152674 | F20: 152674 | G20: $ - | I20: 152674 | J20: =I20=F20 -> TRUE | K20: RAGAZZI SRL | L20: 46340 | M20: 153876
A21: 16 | B21: 3°A - 360 | C21: IANELLO | D21: 0.0103 | E21: 153876 | F21: 153876 | G21: $ - | I21: 153876 | J21: =I21=F21 -> TRUE | K21: RAIMUNDO ANTONIO CLE | L21: 46340 | M21: 177919
A22: 17 | B22: 3°C - 360 | C22: MUSACCHIO | D22: 0.0125 | E22: 366325 | F22: 366325 | G22: $ - | H22: 46346 | I22: 366325 | J22: =I22=F22 -> TRUE | K22: VANESA ALEJANDRA ELI | L22: 46343 | M22: 152674
A23: 18 | B23: 3°B - 360 | C23: ROMBOUTS DIETER | D23: 0.0155 | E23: 216388 | F23: 216388 | G23: $ - | H23: 46330 | I23: 216388 | J23: =I23=F23 -> TRUE | K23: RIVAS CECILIA | L23: 46343 | M23: 177919
A24: 19 | B24: 4°A - 356 | C24: RIONEGRO CARLOS ALBERTO | D24: 0.0171 | E24: 235623 | F24: 216388 | G24: 19235 | H24: 46336 | I24: 216388 | J24: =I24=F24 -> TRUE | K24: PERALTA NATALIA VANESA | L24: 46343 | M24: 153876
A25: 20 | B25: 4°C - 356 | C25: GIANOLA | D25: 0.0107 | E25: 158684 | F25: 158684 | G25: $ - | I25: 158684 | J25: =I25=F25 -> TRUE
A26: 21 | B26: 4°B - 356 | C26: FRANCO | D26: 0.0119 | E26: 173110 | F26: $ - | G26: 173110
A27: 22 | B27: 4°A - 360 | C27: DOMINGUEZ OSVALDO | D27: 0.0119 | E27: 173110 | F27: 173110 | G27: $ - | H27: 46330 | I27: 173110 | J27: =I27=F27 -> TRUE
A28: 23 | B28: 4°C - 360 | C28: CALANDRA | D28: 0.0124 | E28: 179121 | F28: 179121 | G28: $ - | H28: 46336 | I28: 179121 | J28: =I28=F28 -> TRUE
A29: 24 | B29: 4°B - 360 | C29: TAKEDA LAURA NANCY | D29: 0.0156 | E29: 217590 | F29: 217590 | G29: $ - | H29: 46337 | I29: 217590 | J29: =I29=F29 -> TRUE
A30: 25 | B30: 5°A - 356 | C30: SUAREZ PATRICIO | D30: 0.0156 | E30: 217590 | F30: 217590 | G30: $ - | H30: 46330 | I30: 217590 | J30: =I30=F30 -> TRUE
A31: 26 | B31: 5°C - 356 | C31: LANATI | D31: 0.0108 | E31: 159887 | F31: 159887 | G31: $ - | H31: 46344 | I31: 159887 | J31: =I31=F31 -> TRUE
A32: 27 | B32: 5°B - 356 | C32: NIBALDI AGUSTINA | D32: 0.0102 | E32: 152674 | F32: 152674 | G32: $ - | H32: 46330 | I32: 152674 | J32: =I32=F32 -> TRUE
A33: 28 | B33: 5°A - 360 | C33: FLOLASCO SILVINA | D33: 0.0102 | E33: 152674 | F33: 152674 | G33: $ - | H33: 46340 | I33: 152674 | J33: =I33=F33 -> TRUE
A34: 29 | B34: 5°C - 360 | C34: PUMAR RICARDO | D34: 0.0112 | E34: 164695 | F34: 164695 | G34: $ - | H34: 46333 | I34: 164695 | J34: =I34=F34 -> TRUE
A35: 30 | B35: 5°B - 360 | C35: JAIMES MARISA | D35: 0.0175 | E35: 240431 | F35: 240431 | G35: $ - | H35: 46352 | I35: 240431 | J35: =I35=F35 -> TRUE
A36: 31 | B36: 6°A - 356 | C36: FIORENZA | D36: 0.0227 | E36: 302944 | F36: 302944 | G36: $ - | H36: 46336 | I36: 302944 | J36: =I36=F36 -> TRUE
A37: 32 | B37: 6°C - 356 | C37: JUIZ K | D37: 0.0123 | E37: 177919 | F37: 177919 | G37: $ - | I37: 177919 | J37: =I37=F37 -> TRUE
A38: 33 | B38: 6°B - 356 | C38: DELGADO | D38: 0.0118 | E38: 171908 | F38: 171908 | G38: $ - | H38: 46331 | I38: 171908 | J38: =I38=F38 -> TRUE
A39: 34 | B39: 6°A - 360 | C39: IGLESIAS | D39: 0.0139 | E39: 197154 | F39: $ - | G39: 197154
A40: 35 | B40: 6°C - 360 | C40: FAPSA | D40: 0.0123 | E40: 177919 | F40: 177919 | G40: $ - | I40: 177919 | J40: =I40=F40 -> TRUE
...

Sheet Cuota Sindical
A2: FED arg de trab | B2: 16653.65 | C2: 46338 | D2: LA BOLETA SINDICAL NO REFLEJA ESE MONTO
A3: sind un trab fate | B3: 149882.83 | C3: 46338 | D3: LA BOLETA SINDICAL NO REFLEJA ESE MONTO
A4: Fed arg trab ren | B4: 268201.43 | C4: 46338 | D4: LA BOLETA SINDICAL NO REFLEJA ESE MONTO
B5: =B4+B3+B2 -> 434737.91

Sheet Comisiones
A2: Detalle | B2: Fecha | C2: Monto
A3: Comision gastos de cuenta | B3: 46329 | C3: 55000
A4: IVA | B4: 46329 | C4: 11550
A5: Per IVA | B5: 46329 | C5: 6987.75
A6: IMP ING Brutos | B6: 46329 | C6: 4400
A7: Comision transferencia de fondos | B7: 46331 | C7: 1000
A8: IVA | B8: 46331 | C8: 210
A9: Perc IVA | B9: 46331 | C9: 127.05
A10: comisio entre bocs | B10: 46339 | C10: 1000
A11: IVA | B11: 46339 | C11: 210
A12: Perc IVA | B12: 46339 | C12: 127.05
A13: comision dep efvo | B13: 46344 | C13: 5440
A14: IVA | B14: 46344 | C14: 1142.4
... A19: Perc IVA | B19: 46351 | C19: 257.28
C20: =SUM(C3:C19) -> 91028.13

Sheet 25413
A2: Fecha | B2: Monto
A3: 46329 | B3: 467.63
A4: 46330 | B4: 5502.38
A5: 46330 | B5: 10711.22
A6: 46330 | B6: 916.04
A7: 46331 | B7: 40081.61
A8: 46331 | B8: 7675.84
A9: 46333 | B9: 1194.99
A10: 46333 | B10: 9549.93
A11: 46336 | B11: 16220.15
A12: 46337 | B12: 181.99
A13: 46337 | B13: 2221.58
A14: 46337 | B14: 966.53
... A20: 46343 | B20: 5775.41
A21: 46343 | B21: 1298.33 | C21: ok
A22: 46344 | B22: 46.25 | C22: ok
A23: 46344 | B23: 3238.61 | C23: ok
A24: 46346 | B24: 5078.21 | C24: ok
A25: 46346 | B25: 923.26 | C25: ok
A26: 46351 | B26: 8920 | C26: ok
A27: 46351 | B27: 1601.27 | C27: ok
A28: 46352 | B28: 1442.59 | C28: ok
A29: 46353 | B29: 1252.8 | C29: ok
A30: 46354 | B30: 6045.3 | C30: ok
B31: =SUM(B3:B30) -> 161105.22

Sheet Diferencias encontradas
A1: DIFERENCIAS ENTRE LO LOQUIDADO Y LO REALMENTE ABONADO
A2: FECHA | B2: DETALLE | C2: PAGO REALIZADO | D2: EN LIQUIDACIÓN | E2: DIF | F2: OBSERVACION
A3: 46354 | B3: TRANSFERENCIA BANCARIA REALIZADA A MARIA MERCEDES DELJA | C3: 37800 | D3: 0 | E3: =C3-D3 -> 37800 | F3: SIN NINGUN TIPO DE ACLARACIÓN EN LIQUIDACION O COMPROBANTE
A4: 46339 | B4: TRANSFERENCIA DUPLICADA AL SEÑOR CRISTIAN OGAZ AMBAS POR 35000 | C4: 70000 | D4: 35000 | E4: =C4-D4 -> 35000 | F4: TRANSFERENCIA DUPLICADA
A5: 46331 | B5: SEGURIDAD NOVIEMBRE 2025 FACTURA N° 00002-0044 | C5: 2441328.6 | D5: 2372281.2 | E5: =C5-D5 -> 69047.33 | F5: IMPORTE DEVENGADO NO REAL (LIQUIDACION MES ANTERIOR SIN COMPROBANTES EN EL MES ANTERIOR)
A6: 46333 | B6: SEGURO INTEGRAL DEL CONSORCIO | C6: 199165.23 | D6: 199165.25 | E6: =C6-D6 -> -0.02 | F6: DIFERENCIA LIQUIDADA CON ABONADA
A7: 46339 | B7: CLEANSERVICE - PRODUCTOS DE LIMPIEZA, BOLSAS, CONCENTRADO, TRAPO DE PISO | C7: 166205 | D7: 175845 | E7: =C7-D7 -> -9640 | F7: SEGUN ESTO SE ABONO POR MENOS, AUNQUE EL COMPROBANTE NO ES VÁLIDO COMO FACTURA. TENEMOS LA FACTURA?
A8: 46339 | B8: ASCENSORES GUILLERMI - Diferencia de factura de octubre | C8: 169884 | D8: 9414 | E8: =C8-D8 -> 160470 | F8: NO SE PUEDE COMPROBAR DADO QUE NO FACILITARON LOS COMPROBANTES DE ESE MES Y CLARAMENTE EL DEPOSITO ES MUY SUPERIOR
A9: 46338 | B9: CUOTAS SINDICALES | C9: 434737.91 | D9: 410843.14 | E9: =C9-D9 -> 23894.77
A10: 46331 | B10: CARGAS SOCIALES | C10: 1654571.4 | D10: 1546772.5 | E10: =C10-D10 -> 107798.93
A11: 46331 | B11: SUELDO JUAN | C11: 1113138.1 | D11: 1054813.4 | E11: =C11-D11 -> 58324.74
A12: 46331 | B12: SUELDO JAVIER | C12: 711627.9 | D12: 662491.25 | E12: =C12-D12 -> 49136.65
E13: =E12+E11+E10+E9+E8+E7+E6+E5+E4+E3 -> 531832.4
A15: LIQUIDACIÓN SIN PAGO REGISTRADO POR CUENTA BANCARIA
B16: FB SANEAMIENTO MEDIOAMBIENTAL | E16: 85000 | F16: Factura 0001-1751
B17: DESTAPACIONES ITALOAMERICANAS | E17: 350000 | F17: Factura nro 00002-1490
B18: LECOS SERVICIOS | E18: 119000 | F18: Factura nro 00004-0384 armado de tapas cubre toma agua bomberos
B19: PAVON RIVEROS LUIS | E19: 160000 | F19: Factura nro 00003-0161, reparacion cielo raso de cocina, mano de obra y materiales. 1 B 360
E20: =SUM(E16:E19) -> 714000
A21: PAGO REGISTRADOS QUE NO FIGURAN EN EXTRACTO NOVIEMBRE Y SI CONSIDERA LA ADMINISTRACIÓN
B22: CASTRO | C22: 7°C - 360 | D22: 317837
A24: PAGO RECIBIDO BANCARIAMENTE NO ADJUDICADO EN LIQUIDACIÓN
B25: JUAN IGNACIO DIAZ | C25: 46331 | D25: 172139
