Workbook

Sheet 12.2025
B2: LIQUIDACION DE GASTOS
B3: MES DE LIQUIDACIÓN (CIERRE): DICIEMBRE 2025 MES DE VENCIMIENTO DE LA LIQUIDACION: ENERO 2026
B5: Estado de cuentas y prorrateo PERIODO DICIEMBRE 2025 VENCIMIENTO 15/01/2026 Tasa de interés: 7,30%
B6: UF | C6: DEPTO | D6: PROPIETARIOS | E6: PORCENTUAL | F6: SALDO ANTERIOR | G6: PAGOS | H6: SALDO | I6: fecha | J6: Monto
B7: 1 | C7: 1°A - 356 | D7: SEVERINO | E7: 0.0156 | F7: 249457 | G7: 249457 | H7: $ - | I7: 46372 | J7: 249457 | K7: JIGENA MILAGROS
B8: 2 | C8: 1°C - 356 | D8: FERNANDEZ | E8: 0.0107 | F8: 180561 | G8: 180561 | H8: $ - | I8: 46365 | J8: 180561.02
B9: 3 | C9: 1°B - 356 | D9: ALVAREZ MARIA INES | E9: 0.0103 | F9: 174934 | G9: 174934 | H9: $ - | I9: 46375 | J9: 174934
B10: 4 | C10: 1°A - 360 | D10: PERRI | E10: 0.0103 | F10: 174934 | G10: 174934 | H10: $ - | J10: 174934
B11: 5 | C11: 1°C - 360 | D11: BONFANTI SANDRA | E11: 0.0114 | F11: 190407 | G11: 190407 | H11: $ - | I11: 46378 | J11: 190407 | N11: Transferencias sin identificar
B12: 6 | C12: 1°B - 360 | D12: MAGLIOLO SILVIA | E12: 0.0172 | F12: 271991 | G12: 271991 | H12: $ - | I12: 46368 | J12: 271991.06 | N12: 46360 | O12: RODRIGUEZ OUTES, CAM | P12: 173528
B13: 7 | C13: 2°A - 356 | D13: MALDAJAN | E13: 0.016 | F13: 515495 | G13: 242670 | H13: 272825 | I13: 46357 | J13: 242670 | N13: 46360 | O13: JUAN MANUEL FAGUNDEZ | P13: 174934
B14: 8 | C14: 2°C - 356 | D14: CARROSO | E14: 0.0109 | F14: 183374 | G14: 183374 | H14: $ - | I14: 46365 | J14: 183374 | N14: 46360 | O14: COLL\SOFIA TRINIDAD | P14: 203067
B15: 9 | C15: 2°B - 356 | D15: BLAUSTEIN | E15: 0.0103 | F15: 174934 | G15: 174934 | H15: $ - | J15: 174934 | N15: 46361 | O15: HORTIS WENDY | P15: 173528
B16: 10 | C16: 2°A - 360 | D16: LOPARDO | E16: 0.0102 | F16: 173528 | G16: 173528 | H16: $ - | J16: 173528 | N16: 46365 | O16: JUAN IGNACIO SAEZ GA | P16: 180561
B17: 11 | C17: 2°C - 360 | D17: MENA | E17: 0.0107 | F17: 180561 | G17: 180561 | H17: $ - | J17: 180561 | N17: 46365 | O17: COMBER|DENISE | P17: 173528
B18: 12 | C18: 2°B - 360 | D18: PUMA ROSA | E18: 0.0155 | F18: 248079 | G18: 248079 | H18: $ - | I18: 46372 | J18: 248079 | K18: ALFREDO JOAQUIN DI C | N18: 46365 | O18: ROSA ANTONIA GUALLIN | P18: 174934
B19: 13 | C19: 3°A - 356 | D19: GRIMM | E19: 0.0159 | F19: 253705 | G19: 253705 | H19: $ - | I19: 46360 | J19: 434233 | N19: 46367 | O19: RAIMUNDO ANTONIO CLE | P19: 203067
B20: 14 | C20: 3°C - 356 | D20: GRIMM | E20: 0.0107 | F20: 180561 | G20: 180528 | H20: 33 | I20: 46360 | N20: 46368 | O20: AGUSTINA CASTRO ACEV | P20: 173528
B21: 15 | C21: 3°B - 356 | D21: FERNANDEZ | E21: 0.0102 | F21: 173528 | G21: 173528 | H21: $ - | J21: 173528 | N21: 46371 | O21: RIVAS CECILIA ALEJAN | P21: 203067
B22: 16 | C22: 3°A - 360 | D22: IANELLO | E22: 0.0103 | F22: 174934 | G22: 174934 | H22: $ - | J22: 174934 | N22: 46371 | O22: RAGAZZI SRL | P22: 174934
B23: 17 | C23: 3°C - 360 | D23: MUSACCHIO | E23: 0.0125 | F23: 205880 | G23: $ - | H23: 205880 | N23: 46372 | O23: KURT ZIEGER | P23: 173528
B24: 18 | C24: 3°B - 360 | D24: ROMBOUTS DIETER | E24: 0.0155 | F24: 248079 | G24: 248079 | H24: $ - | I24: 46365 | J24: 248079 | N24: 46379 | O24: PERALTA NATALIA VANE | P24: 174934
B25: 19 | C25: 4°A - 356 | D25: RIONEGRO CARLOS ALBERTO | E25: 0.0171 | F25: 291223 | G25: 291223 | H25: $ - | I25: 46378 | J25: 291223
B26: 20 | C26: 4°C - 356 | D26: GIANOLA | E26: 0.0107 | F26: 180561 | G26: 180561 | H26: $ - | I26: 46365 | J26: 180561 | K26: JONTE LUCAS MARTIN
B27: 21 | C27: 4°B - 356 | D27: FRANCO | E27: 0.0119 | F27: 383188 | G27: 383188 | H27: $ - | I27: 46371 | J27: 383188 | K27: CESAR DAVID SAMANIEG
B28: 22 | C28: 4°A - 360 | D28: DOMINGUEZ OSVALDO | E28: 0.0119 | F28: 197440 | G28: 197440 | H28: $ - | I28: 46360 | J28: 197440
B29: 23 | C29: 4°C - 360 | D29: CALANDRA | E29: 0.0124 | F29: 204473 | G29: 204473 | H29: $ - | I29: 46368 | J29: 204473 | K29: SILVIA ALICIA CASTRO
B30: 24 | C30: 4°B - 360 | D30: TAKEDA LAURA NANCY | E30: 0.0156 | F30: 249485 | G30: 249485 | H30: $ - | I30: 46371 | J30: 249485
B31: 25 | C31: 5°A - 356 | D31: SUAREZ PATRICIO | E31: 0.0156 | F31: 249485 | G31: 249485 | H31: $ - | I31: 46361 | J31: 249485
B32: 26 | C32: 5°C - 356 | D32: LANATI | E32: 0.0108 | F32: 181968 | G32: 204537 | H32: -22569 | I32: 46371 | J32: =M32+O32 -> 204537 | K32: SAUL JAVIER MILLAN A | L32: 45993 | M32: 159887 | N32: 46371 | O32: 44650
B33: 27 | C33: 5°B - 356 | D33: NIBALI AGUSTINA DENISE | E33: 0.0102 | F33: 173528 | G33: 173528 | H33: $ - | I33: 46365 | J33: 173528
B34: 28 | C34: 5°A - 360 | D34: FLOLASCO SILVINA | E34: 0.0102 | F34: 173528 | G34: 173528 | H34: $ - | I34: 46373 | J34: 173528
B35: 29 | C35: 5°C - 360 | D35: PUMAR RICARDO | E35: 0.0112 | F35: 187594 | G35: 187594 | H35: $ - | I35: 46365 | J35: 187594
B36: 30 | C36: 5°B - 360 | D36: JAIMES MARISA | E36: 0.0175 | F36: 276211 | G36: 276211 | H36: $ - | I36: 46385 | J36: 276211
B37: 31 | C37: 6°A - 356 | D37: FIORENZA | E37: 0.0227 | F37: 349355 | G37: 349355 | H37: $ - | I37: 46361 | J37: 349355 | K37: UNICO PAGO DE 597434
B38: 32 | C38: 6°C - 356 | D38: JUIZ K | E38: 0.0123 | F38: 203067 | G38: 203067 | H38: $ - | J38: 203067
B39: 33 | C39: 6°B - 356 | D39: DELGADO | E39: 0.0118 | F39: 196034 | G39: 196034 | H39: $ - | I39: 46361 | J39: 196034 | K39: ROSSI, GISELLE ANALIA
B40: 34 | C40: 6°A - 360 | D40: IGLESIAS | E40: 0.0139 | F40: 437118 | G40: 437118 | H40: 0 | I40: 46371 | J40: =M40+P40 -> 437118 | K40: MATIAS JULIAN VERA | L40: 46357 | M40: 197154 | N40: INGRESO EXP OCT | O40: 46371 | P40: 239964
B41: 35 | C41: 6°C - 360 | D41: FAPSA | E41: 0.0123 | F41: 203067 | G41: 203067 | H41: $ - | J41: 203067
B42: 36 | C42: 6°B - 360 | D42: GIANCASPRO | E42: 0.0157 | F42: 250892 | G42: 250892 | H42: $ - | I42: 46371 | J42: 250892.36 | K42: GARCIA MISA CAMILA
...

Sheet Cuota Sindical
A1: FECHA | B1: DETALLE | C1: MONTO
A2: 46368 | B2: FED ARG DE TRAB | C2: 15578.92
A3: 46368 | B3: SIND UN TRAB REN | C3: 140210.29
A4: 46368 | B4: FED ARG TRAB REN | C4: 255053.93
C5: =SUM(C2:C4) -> 410843.14

Sheet Comisiones
A1: Detalle | B1: Fecha | C1: Monto
A2: COMISION SERVICIO DE CUENTA | B2: 46357 | C2: 55000
A3: IVA | B3: 46357 | C3: 11550
A4: PERCEP IVA | B4: 46357 | C4: 6987.75
A5: IMP ING BRUTOS | B5: 46357 | C5: 4400
A6: COM GESTION TRANS FONDOS ENTRE BANCOS | B6: 46361 | C6: 1000
A7: IVA | B7: 46361 | C7: 210
A8: PERCEP IVA | B8: 46361 | C8: 127.05
A9: COM GESTION TRANS FONDOS ENTRE BANCOS | B9: 46368 | C9: 1000
A10: IVA | B10: 46368 | C10: 210
A11: PERCEP IVA | B11: 46368 | C11: 127.05
A12: COMISION DEPOSITOS EN EVO | B12: 46372 | C12: 1116.25
A13: IVA | B13: 46372 | C13: 234.41
... A20: PERCEP IVA | B20: 46379 | C20: 587.61
C21: =C20+C19+C18+C17+C16+C15+C14+C13+C12+C11+C10+C9+C8+C7+C6+C5+C4+C3+C2 -> 90825.45

Sheet 25413
A1: Fecha | B1: Monto
A2: 46357 | B2: 2638.94
A3: 46357 | B3: 467.63
A4: 46358 | B4: 959.32
A5: 46360 | B5: 1271.14
A6: 46360 | B6: 10472.82
A7: 46360 | B7: 1218.4
A8: 46361 | B8: 33410.85
A9: 46361 | B9: 11696.78
A10: 46365 | B10: 15793.04
A11: 46365 | B11: 1091.8
A12: 46366 | B12: 3665.92
A13: 46367 | B13: 1218.4
... A31: 46386 | B31: 9364.27
B32: =SUM(B2:B31) -> 207815.27

Sheet LA UNION E HIJS
A1: 46386 | B1: 22895.81 | C1: CON FACTURA
A2: 46386 | B2: 23598.23 | C2: CON FACTURA
A3: 46386 | B3: 24361.2 | C3: CON FACTURA
A4: 46386 | B4: 520591.32 | C4: CON FACTURA
A5: 46386 | B5: 769264.83 | C5: CON FACTURA
A6: LIQUIDADO DICIEMBRE | B6: =SUM(B1:B5) -> 1360711.4

Sheet Diferencias Encontradas
A2: DIFERENCIAS ENTRE LO LOQUIDADO Y LO REALMENTE ABONADO
A3: FECHA | B3: DETALLE | C3: PAGO REALIZADO | D3: EN LIQUIDACIÓN | E3: DIF | F3: OBSERVACION
A4: 46361 | B4: SUELDO JUAN | C4: ='12.2025'!L114 -> 1054814 | D4: 1089415 | E4: =C4-D4 -> -34601 | F4: IMPORTE DEVENGADO NO REAL (LIQUIDACION MES ANTERIOR $ 1,054,813.41)
A5: 46361 | B5: SUELDO JAVIER | C5: ='12.2025'!L133 -> 682492 | D5: 681302 | E5: =C5-D5 -> 1190 | F5: IMPORTE DEVENGADO NO REAL (LIQUIDACION MES ANTERIOR $ 662,491.25) SE DEPOSITARON 20000 DE MAS
A6: 46361 | B6: SUELDO RAMIREZ | C6: ='12.2025'!L149 -> 687551 | D6: 688435 | E6: =C6-D6 -> -884 | F6: IMPORTE DEVENGADO NO REAL (LIQUIDACION MES ANTERIOR $ 745,574.00) SE DEPOSITARON 58023 DE MENOS
A7: 46374 | B7: AGUINALDO JUAN | C7: ='12.2025'!L115 -> 676931.22 | D7: 1287347 | E7: =C7-D7 -> -610415.78 | F7: IMPORTE LIQUIDADO EN EL MES ANTERIOR CON PROVISION TOTAL MENOR AL REAL - AUNQUE EL PAGO CORRESPONDE LA RECAUDACION FUE MENOR
A8: 46374 | B8: AGUINALDO JAVIER | C8: ='12.2025'!L134 -> 449120.28 | D8: 0 | E8: =C8-D8 -> 449120.28 | F8: IMPORTE LIQUIDADO EN EL MES ANTERIOR CON PROVISION TOTAL MENOR AL REAL - AUNQUE EL PAGO CORRESPONDE LA RECAUDACION FUE MENOR
A9: 46374 | B9: AGUINALDO RAMIREZ | C9: ='12.2025'!L150 -> 501470.1 | D9: 0 | E9: =C9-D9 -> 501470.1 | F9: IMPORTE LIQUIDADO EN EL MES ANTERIOR CON PROVISION TOTAL MENOR AL REAL - AUNQUE EL PAGO CORRESPONDE LA RECAUDACION FUE MENOR
A10: 46368 | B10: CARGAS SOCIALES | C10: ='12.2025'!L154 -> 1546772.5 | D10: ='12.2025'!F154 -> 2526913.6 | E10: =C10-D10 -> -980141.07 | F10: IMPORTE DEVENGADO NO REAL (LIQUIDACION MES ANTERIOR $ 1,546,772.50)
A11: 46368 | B11: FED ARG DE TRAB | C11: 15578.92 | D11: 679584.04 | E11: =C11-D11 -> -664005.12 | F11: IMPORTE DEVENGADO NO REAL (LIQUIDACION MES ANTERIOR CON COMPROBANTES EN EL MES ANTERIOR)
A12: 46368 | B12: SIND UN TRAB REN | C12: 140210.29 | D12: 0 | E12: =C12-D12 -> 140210.29 | F12: IMPORTE DEVENGADO NO REAL (LIQUIDACION MES ANTERIOR CON COMPROBANTES EN EL MES ANTERIOR)
A13: 46368 | B13: FED ARG TRAB REN | C13: 255053.93 | D13: 0 | E13: =C13-D13 -> 255053.93 | F13: IMPORTE DEVENGADO NO REAL (LIQUIDACION MES ANTERIOR CON COMPROBANTES EN EL MES ANTERIOR)
A14: LA UNION E HIJOS SRL | B14: COMPRA DE PINTURA CUOATA 01/02 | C14: 1360711.4 | D14: 3500000 | E14: =C14-D14 -> -2139288.6 | F14: SE LIQUIDO UN GASTO EXTRAORDINARIO MUY SUPERIOR A LO FINALMENTE FACTURADO Y ESTA RECAUDACIÓN NO FUE INCLUIDA EN EL RESUMEN DE FDR QUE IBAN DESTINADOS A PINTURA, MIENTRAS QUE LOS GASTOS SI ESTAN DETALLADOS.
A15: 46368 | B15: CLEANNIG SERVICE - MATERIALES DE LIMPIEZA | C15: 175845 | D15: 212900 | E15: =C15-D15 -> -37055 | F15: SEGUN ESTO SE ABONO POR MENOS, AUNQUE EL COMPROBANTE NO ES VÁLIDO COMO FACTURA. TENEMOS LA FACTURA?
A16: 46361 | B16: SEGURIDAD NOVIEMBRE 2025 FACTURA N° 00002-0044 | C16: 2372281.2 | D16: 3704325 | E16: =D16-C16 -> 1332043.8 | F16: IMPORTE DEVENGADO NO REAL (LIQUIDACION MES ANTERIOR CON COMPROBANTES EN EL MES ANTERIOR)
A18: LIQUIDADO SIN PAGO REGISTRADO EN CUENTA
A19: YPF CICLOS | B19: COMPRA DE COMBUSTIBLE FACT Nro 00011-53269 | C19: 32000.04 | D19: COMPROBANTE CON FECHA 14/10 21:25
A20: YPF CICLOS | B20: COMPRA DE COMBUTIBLR FACT.Nro 0001-53270 | C20: 32000.04 | D20: COMPROBANTE CON FECHA 14/10 21:27
A21: ASCENSORES GUILLEMI | B21: Mantenimiento ascensores DICIEMBRE | C21: 87866.77 | D21: FACTURA DE 120000 FECHA 5/1
A22: FOTOCOPIAS DE EXPENSAS NOVIEMBRE | C22: 18900 | D22: SIN COMPROBANTE
A24: PAGO REGISTRADOS QUE NO FIGURAN EN ESTRACTO Y SI CONSIDERA LA ADMINISTRACIÓN
B25: CALOGNE RICARDO | C25: 9°A - 356 | D25: 65000
A27: GASTOS NO LIQUIDADOS QUE FUERON DEBITADOS DE CUENTA
A28: 46361 | B28: RAFAEL MOREL ROMAN | C28: 700000 | D28: CON RECIBI FECHA 5/12 | E28: PUESTO EN ESE RESUMEN DE FDR MAL COMPUTADO
A29: 46368 | B29: LUIS DE LA PAS PAVON | C29: 160000 | D29: SIN NINGUN COMPROBANTE EN ESTE MES | E29: ENTIENDO QUE PAGARON LA DIFERENCIA LIQUIDADA EL MES PASADO EN ESTE MES SALDANDO EL ERROR MARCADO EL MES ANTERIOR
A30: 46368 | B30: RAFAEL MOREL ROMAN | C30: 1000000 | D30: CON RECIBI FECHA 12/12 | E30: PUESTO EN ESE RESUMEN DE FDR MAL COMPUTADO
A31: 46374 | B31: RAFAEL MOREL ROMAN | C31: 1700000 | D31: CON RECIBI FECHA 18/12 | E31: PUESTO EN ESE RESUMEN DE FDR MAL COMPUTADO
A32: 46378 | B32: RAFAEL MOREL ROMAN | C32: 1500000 | D32: CON RECIBI FECHA 29/12 | E32: PUESTO EN ESE RESUMEN DE FDR MAL COMPUTADO
